# Relatório de Diagnóstico de Testes: `py_main_processor_v2.py`Este relatório detalha os erros encontrados na última execução dos testes automatizados para `py_main_processor_v2.py`, incluindo a localização, causa e sugestões de ajuste. O status de cada item será marcado com `[ ]` (pendente) ou `[x]` (concluído).## Data da Execução: 14 de julho de 2025## Resultados Gerais:- **Total de Testes:** 12- **Testes Passados:** 7- **Testes Falhos:** 5- **Warnings:** 16---### 1. Erro: `AssertionError` no `test_user_not_registered`- **Status:** `[ ]` Pendente- **Localização:** `C:\source\IAResipa\tests\main_processor_v2_tests\test_main_processor_v2.py:42`- **Diagnóstico Detalhado:** O teste espera uma mensagem de "Olá! Parece que você não está cadastrado. Por favor, faça seu cadastro para continuar.", mas o sistema retornou "Bem-vindo de volta, 5511999999999! Como posso ajudar hoje?". Isso indica que o número de telefone (`5511999999999`) usado neste teste já está cadastrado no Supabase, o que invalida o cenário de "usuário não cadastrado".- **Sugestão de Ajuste:**    - **Opção A (Recomendada para testes):** Implementar uma estratégia para garantir que o ambiente de teste do Supabase seja limpo *antes* de cada execução de teste, ou pelo menos antes de testes que dependem de um estado limpo. Isso pode ser feito executando o `clear_test_data.sql` manualmente ou integrando-o ao `pytest` (por exemplo, usando um fixture `session` ou `module` que limpa o DB).    - **Opção B (Menos ideal para testes unitários):** Se a limpeza do DB não for viável para cada teste, o teste `test_user_not_registered` precisaria de uma lógica mais robusta para gerar um número que *realmente* não exista no DB antes de fazer a asserção.---### 2. Erro: `AssertionError` no `test_check_active_reservations_no_reservations`- **Status:** `[ ]` Pendente- **Localização:** `C:\source\IAResipa\tests\main_processor_v2_tests\test_main_processor_v2.py:130`- **Diagnóstico Detalhado:** O teste espera a mensagem "Você não possui reservas ativas no momento.", mas a resposta real foi "Gerenciando suas reservas: minhas reservas". Isso indica que a mensagem "minhas reservas" está sendo roteada para `handle_manage_reservations` em vez de `check_active_reservations` dentro de `handle_reservation` (ou a lógica de `handle_manage_reservations` não está retornando a mensagem esperada para este cenário).- **Sugestão de Ajuste:** Em `C:\source\IAResipa\03.src\resipaia\py_main_processor_v2.py`, revisar a lógica de roteamento dentro de `process_message_logic` e/ou `handle_reservation` para garantir que a intenção "minhas reservas" seja direcionada corretamente para a função `check_active_reservations` e que esta retorne a mensagem esperada.---### 3. Erro: `AssertionError` no `test_check_availability_no_resources`- **Status:** `[ ]` Pendente- **Localização:** `C:\source\IAResipa\tests\main_processor_v2_tests\test_main_processor_v2.py:142`- **Diagnóstico Detalhado:** O teste espera a mensagem "Nenhum recurso disponível no momento.", mas a resposta real foi "Consultando Gemini para: opções disponíveis". Isso indica que a mensagem "opções disponíveis" está sendo roteada para `handle_gemini_query` em vez de `check_availability` dentro de `handle_reservation`.- **Sugestão de Ajuste:** Similar ao erro anterior, em `C:\source\IAResipa\03.src\resipaia\py_main_processor_v2.py`, revisar a lógica de roteamento dentro de `process_message_logic` e/ou `handle_reservation` para garantir que a intenção "opções disponíveis" seja direcionada corretamente para a função `check_availability` e que esta retorne a mensagem esperada.---### 4. Erro: `AssertionError` e `invalid input syntax for type uuid` no `test_create_provisional_reservation_success`- **Status:** `[ ]` Pendente- **Localização:** `C:\source\IAResipa\tests\main_processor_v2_tests\test_main_processor_v2.py:154` (AssertionError) e `C:\source\IAResipa\03.src\resipaia\py_04_reservation_manager.py:56` (erro de UUID no log)- **Diagnóstico Detalhado:** O teste espera a mensagem "Sua reserva provisória foi criada com sucesso!", mas a chamada ao Supabase falha com "invalid input syntax for type uuid" porque o `user_id` que está sendo passado para `create_provisional_reservation` é o número de telefone (string), enquanto a coluna `user_id` na tabela `reservas` do Supabase espera um UUID.- **Sugestão de Ajuste:** Em `C:\source\IAResipa\03.src\resipaia\py_main_processor_v2.py`, na função `handle_reservation`, antes de chamar `create_provisional_reservation`, o `user_id` deve ser obtido do `message_details['user_id']` (que é preenchido por `handle_user_check` com o UUID do usuário). Se `message_details['user_id']` não estiver presente, o usuário deve ser instruído a se cadastrar ou verificar seu status.---### 5. Erro: `AssertionError` e `invalid input syntax for type uuid` no `test_add_to_waiting_list_success`- **Status:** `[ ]` Pendente- **Localização:** `C:\source\IAResipa\tests\main_processor_v2_tests\test_main_processor_v2.py:166` (AssertionError) e `C:\source\IAResipa\03.src\resipaia\py_04_reservation_manager.py:107` (erro de UUID no log)- **Diagnóstico Detalhado:** Similar ao erro anterior, o `user_id` que está sendo passado para `add_to_waiting_list` é o número de telefone (string), mas a coluna `user_id` na tabela `lista_espera` do Supabase espera um UUID.- **Sugestão de Ajuste:** Em `C:\source\IAResipa\03.src\resipaia\py_main_processor_v2.py`, na função `handle_reservation`, antes de chamar `add_to_waiting_list`, o `user_id` deve ser obtido do `message_details['user_id']` (que é preenchido por `handle_user_check` com o UUID do usuário).---### 6. Erro: `AssertionError` no `test_admin_removes_user`- **Status:** `[ ]` Pendente- **Localização:** `C:\source\IAResipa\tests\main_processor_v2_tests\test_main_processor_v2.py:197`- **Diagnóstico Detalhado:** O teste espera a mensagem "Usuário XXXXXXXXXXX removido com sucesso!", mas a resposta real pode ser diferente se a remoção falhar ou se a mensagem de sucesso não for exatamente essa. O log indica que o teste `test_admin_removes_user` falhou com um `NameError: name 'datetime' is not defined` na linha 4 do arquivo de teste, o que significa que a importação de `datetime` não estava presente ou foi perdida.- **Sugestão de Ajuste:** Adicionar `from datetime import datetime` no início do arquivo `C:\source\IAResipa\tests\main_processor_v2_tests\test_main_processor_v2.py`. Após isso, verificar a mensagem de sucesso retornada por `delete_user` em `py_05_user_registration_logic.py` e ajustar a asserção no teste para corresponder.---### Warnings (DeprecationWarning)- **Status:** `[ ]` Pendente (para análise futura, não bloqueante)- **Localização:** Várias linhas em `C:\Program Files\Python313\Lib\site-packages\supabase\_sync\client.py`- **Diagnóstico Detalhado:** Estes são avisos de descontinuação da biblioteca `supabase-py` relacionados aos parâmetros `timeout` e `verify`. Eles não são erros que impedem a execução, mas indicam que o uso desses parâmetros será removido em futuras versões da biblioteca.- **Sugestão de Ajuste:** Em uma refatoração futura, ajustar a inicialização do cliente Supabase para configurar `timeout` e `verify` diretamente no cliente HTTP subjacente, conforme a documentação da biblioteca `supabase-py`.